<?xml version="1.0" ?>
<!-- =================================================================================== -->
<!-- |    This document was autogenerated by xacro from scara.xacro                    | -->
<!-- |    EDITING THIS FILE BY HAND IS NOT RECOMMENDED                                 | -->
<!-- =================================================================================== -->
<robot name="scara" xmlns:xacro="http://www.ros.org/wiki/xacro">
  <link name="base_link">
  </link>
  <link name="link_1">
  </link>
  <link name="link_2">
  </link>
  <link name="link_3">
  </link>
  <joint name="link1_to_base" type="revolute">
    <parent link="base_link"/>
    <child link="link_1"/>
    <origin xyz="0 0 0.129"/>
    <axis xyz="0 0 1"/>
    <limit effort="300" lower="-3.14" upper="3.14" velocity="0.1"/>
  </joint>
  <joint name="link2_to_link1" type="revolute">
    <parent link="link_1"/>
    <child link="link_2"/>
    <origin xyz="0.12 0 0"/>
    <axis xyz="0 0 1"/>
    <limit effort="300" lower="-3.14" upper="3.14" velocity="0.1"/>
  </joint>
  <joint name="link3_to_link2" type="prismatic">
    <parent link="link_2"/>
    <child link="link_3"/>
    <origin xyz="0.13 0 0"/>
    <axis xyz="0 0 1"/>
    <limit effort="300" lower="-0.15" upper="0" velocity="0.1"/>
  </joint>
</robot>

